Time slot   0
ld_routine
        Loaded a process at input/proc/p0s, PID: 1 PRIO: 0
Time slot   1
        CPU 0: Dispatched process  1
        Loaded a process at input/proc/p1s, PID: 2 PRIO: 15
Time slot   2
print_pgtbl:
 PDG=0000794a78000bb0 P4g=0000794a78001bc0 PUD=0000794a78002bd0 PMD=0000794a78003be0
        CPU 1: Dispatched process  2
Time slot   3
print_pgtbl:
 PDG=0000794a78000bb0 P4g=0000794a78001bc0 PUD=0000794a78002bd0 PMD=0000794a78003be0
Time slot   4
        Loaded a process at input/proc/p1s, PID: 3 PRIO: 0
Time slot   5
print_pgtbl:
 PDG=0000794a78000bb0 P4g=0000794a78001bc0 PUD=0000794a78002bd0 PMD=0000794a78003be0
        Loaded a process at input/proc/p1s, PID: 4 PRIO: 0
print_pgtbl:
 PDG=0000794a78000bb0 P4g=0000794a78001bc0 PUD=0000794a78002bd0 PMD=0000794a78003be0
Time slot   6
Time slot   7
        CPU 0: Put process  1 to run queue
        CPU 0: Dispatched process  3
Time slot   8
        CPU 1: Put process  2 to run queue
        CPU 1: Dispatched process  4
Time slot   9
Time slot  10
Time slot  11
Time slot  12
        CPU 0: Put process  3 to run queue
        CPU 0: Dispatched process  1
print_pgtbl:
 PDG=0000794a78000bb0 P4g=0000794a78001bc0 PUD=0000794a78002bd0 PMD=0000794a78003be0
Time slot  13
Time slot  14
print_pgtbl:
 PDG=0000794a78000bb0 P4g=0000794a78001bc0 PUD=0000794a78002bd0 PMD=0000794a78003be0
        CPU 1: Put process  4 to run queue
        CPU 1: Dispatched process  3
print_pgtbl:
 PDG=0000794a78000bb0 P4g=0000794a78001bc0 PUD=0000794a78002bd0 PMD=0000794a78003be0
Time slot  15
Time slot  16
print_pgtbl:
 PDG=0000794a78000bb0 P4g=0000794a78001bc0 PUD=0000794a78002bd0 PMD=0000794a78003be0
Time slot  17
print_pgtbl:
 PDG=0000794a78000bb0 P4g=0000794a78001bc0 PUD=0000794a78002bd0 PMD=0000794a78003be0
Time slot  18
        CPU 1: Processed  3 has finished
        CPU 0: Put process  1 to run queue
        CPU 1: Dispatched process  4
        CPU 0: Dispatched process  1
Time slot  19
Time slot  20
Time slot  21
        CPU 0: Processed  1 has finished
        CPU 0: Dispatched process  2
Time slot  22
        CPU 1: Processed  4 has finished
        CPU 1 stopped
Time slot  23
Time slot  24
Time slot  25
        CPU 0: Processed  2 has finished
        CPU 0 stopped
root@Kan:/mnt/d/OS_Assignment/ossim_lamiaatrium# ./os os_1_mlq_paging
Time slot   0
ld_routine
        Loaded a process at input/proc/p0s, PID: 1 PRIO: 130
        CPU 3: Dispatched process  1
Time slot   1
Time slot   2
print_pgtbl:
 PDG=00007fe018000bb0 P4g=00007fe018001bc0 PUD=00007fe018002bd0 PMD=00007fe018003be0
        Loaded a process at input/proc/s3, PID: 2 PRIO: 39
        CPU 3: Put process  1 to run queue
        CPU 3: Dispatched process  1
print_pgtbl:
 PDG=00007fe018000bb0 P4g=00007fe018001bc0 PUD=00007fe018002bd0 PMD=00007fe018003be0
Time slot   3
        CPU 2: Dispatched process  2
        Loaded a process at input/proc/m1s, PID: 3 PRIO: 15
Time slot   4
        CPU 1: Dispatched process  3
print_pgtbl:
 PDG=00007fe01c000bb0 P4g=00007fe01c001bc0 PUD=00007fe01c002bd0 PMD=00007fe01c003be0
        CPU 3: Put process  1 to run queue
        CPU 3: Dispatched process  1
print_pgtbl:
 PDG=00007fe018000bb0 P4g=00007fe018001bc0 PUD=00007fe018002bd0 PMD=00007fe018003be0
Time slot   5
print_pgtbl:
 PDG=00007fe01c000bb0 P4g=00007fe01c001bc0 PUD=00007fe01c002bd0 PMD=00007fe01c003be0
        CPU 2: Put process  2 to run queue
        CPU 2: Dispatched process  2
        Loaded a process at input/proc/s2, PID: 4 PRIO: 120
print_pgtbl:
Time slot   6
        CPU 1: Put process  3 to run queue
        CPU 1: Dispatched process  3
 PDG=00007fe018000bb0 P4g=00007fe018001bc0 PUD=00007fe018002bd0 PMD=00007fe018003be0
        CPU 3: Put process  1 to run queue
        CPU 3: Dispatched process  1
print_pgtbl:
 PDG=00007fe018000bb0 P4g=00007fe018001bc0 PUD=00007fe018002bd0 PMD=00007fe018003be0
        CPU 0: Dispatched process  4
        CPU 2: Put process  2 to run queue
        CPU 2: Dispatched process  2
print_pgtbl:
 PDG=00007fe01c000bb0 P4g=00007fe01c001bc0 PUD=00007fe01c002bd0 PMD=00007fe01c003be0
Time slot   7
        Loaded a process at input/proc/m0s, PID: 5 PRIO: 120
print_pgtbl:
 PDG=00007fe018000bb0 P4g=00007fe018001bc0 PUD=00007fe018002bd0 PMD=00007fe018003be0
        CPU 1: Put process  3 to run queue
        CPU 1: Dispatched process  3
Time slot   8
        Loaded a process at input/proc/p1s, PID: 6 PRIO: 15
Time slot   9
        CPU 3: Put process  1 to run queue
        CPU 3: Dispatched process  6
        CPU 2: Put process  2 to run queue
        CPU 2: Dispatched process  2
        CPU 0: Put process  4 to run queue
        CPU 0: Dispatched process  5
print_pgtbl:
 PDG=00007fe010000bb0 P4g=00007fe010001bc0 PUD=00007fe010002bd0 PMD=00007fe010003be0
Time slot  10
        CPU 1: Processed  3 has finished
        CPU 1: Dispatched process  4
print_pgtbl:
 PDG=00007fe010000bb0 P4g=00007fe010001bc0 PUD=00007fe010002bd0 PMD=00007fe010003be0
        Loaded a process at input/proc/s0, PID: 7 PRIO: 38
        CPU 3: Put process  6 to run queue
        CPU 3: Dispatched process  6
        CPU 2: Put process  2 to run queue
        CPU 2: Dispatched process  7
Time slot  11
        CPU 0: Put process  5 to run queue
        CPU 0: Dispatched process  2
Time slot  12
        CPU 1: Put process  4 to run queue
        CPU 1: Dispatched process  5
        CPU 2: Put process  7 to run queue
print_pgtbl:
 PDG=00007fe010000bb0 P4g=00007fe010001bc0 PUD=00007fe010002bd0 PMD=00007fe010003be0
        CPU 0: Put process  2 to run queue
        CPU 0: Dispatched process  2
        CPU 3: Put process  6 to run queue
        CPU 3: Dispatched process  6
        CPU 2: Dispatched process  7
Time slot  13
Time slot  14
        CPU 0: Processed  2 has finished
        CPU 0: Dispatched process  4
        CPU 1: Put process  5 to run queue
        CPU 1: Dispatched process  5
print_pgtbl:
 PDG=00007fe010000bb0 P4g=00007fe010001bc0 PUD=00007fe010002bd0 PMD=00007fe010003be0
        CPU 3: Put process  6 to run queue
Time slot  15
        CPU 2: Put process  7 to run queue
        CPU 2: Dispatched process  7
print_pgtbl:
 PDG=00007fe010000bb0 P4g=00007fe010001bc0 PUD=00007fe010002bd0 PMD=00007fe010003be0
        CPU 3: Dispatched process  6
        Loaded a process at input/proc/s1, PID: 8 PRIO: 0
        CPU 1: Processed  5 has finished
        CPU 1: Dispatched process  8
        CPU 0: Put process  4 to run queue
Time slot  16
        CPU 0: Dispatched process  4
        CPU 3: Put process  6 to run queue
        CPU 2: Put process  7 to run queue
        CPU 2: Dispatched process  7
        CPU 3: Dispatched process  6
Time slot  17
        CPU 1: Put process  8 to run queue
        CPU 1: Dispatched process  8
        CPU 0: Put process  4 to run queue
Time slot  18
        CPU 0: Dispatched process  4
        CPU 3: Processed  6 has finished
        CPU 2: Put process  7 to run queue
Time slot  19
        CPU 3: Dispatched process  1
print_pgtbl:
 PDG=00007fe018000bb0 P4g=00007fe018001bc0 PUD=00007fe018002bd0 PMD=00007fe018003be0
        CPU 2: Dispatched process  7
print_pgtbl:
        CPU 1: Put process  8 to run queue
Time slot  20
 PDG=00007fe018000bb0 P4g=00007fe018001bc0 PUD=00007fe018002bd0 PMD=00007fe018003be0
        CPU 1: Dispatched process  8
        CPU 0: Put process  4 to run queue
        CPU 0: Dispatched process  4
        CPU 2: Put process  7 to run queue
        CPU 2: Dispatched process  7
        CPU 3: Put process  1 to run queue
        CPU 3: Dispatched process  1
print_pgtbl:
 PDG=00007fe018000bb0 P4g=00007fe018001bc0 PUD=00007fe018002bd0 PMD=00007fe018003be0
Time slot  21
        CPU 1: Put process  8 to run queue
        CPU 1: Dispatched process  8
        CPU 0: Processed  4 has finished
        CPU 0 stopped
Time slot  22
        CPU 3: Put process  1 to run queue
Time slot  23
        CPU 3: Dispatched process  1
        CPU 1: Processed  8 has finished
        CPU 1 stopped
        CPU 2: Put process  7 to run queue
        CPU 2: Dispatched process  7
Time slot  24
        CPU 3: Processed  1 has finished
        CPU 3 stopped
Time slot  25
        CPU 2: Put process  7 to run queue
        CPU 2: Dispatched process  7
Time slot  26
        CPU 2: Processed  7 has finished
        CPU 2 stopped